Workbook

Sheet Bets
A1: Bet ID | B1: Bettor | C1: Date posted (CT) | D1: Day of week (posted) | E1: Game date | F1: Game day of week | G1: Game kickoff time (ET) | H1: Prime time (Y/N) | I1: Prime time slot | J1: Sport category | K1: League/event | L1: Bet type | M1: Selection/legs | N1: # legs | O1: Odds (American) | P1: Odds (decimal) | Q1: Stake $ | R1: Units | S1: To win/payout $ (total return) | T1: Book/platform | U1: Result | V1: Profit/Loss $ | W1: Profit/Loss units | X1: Result source | Y1: Sponsored/promo flag | Z1: Post URL | AA1: Notes | AB1: Single vs parlay | AC1: Settled $ stake (helper) | AD1: Settled units (helper)
A2: T-578065 | B2: Trent | C2: 46235.522 | D2: =IF(C2="","",TEXT(C2,"dddd")) | E2: 46235 | F2: =IF(E2="","",TEXT(E2,"dddd")) | G2: 9:38 PM | H2: N | J2: MLB | K2: MLB | L2: parlay | M2: TB ML -160; PHI ML -138; LAD ML -156; MIL ML -112 | N2: 4 | O2: +770 | P2: 8.7 | Q2: 1000 | S2: 7700 | T2: Pikkit | U2: L | V2: =IF(NOT(ISNUMBER(Q2)),"",IF(U2="W",IF(ISNUMBER(S2),S2-Q2,IF(ISNUMBER(P2),Q2*(P2-1),"")),IF(U2="L",-Q2,IF(U2="Push",0,"")))) | W2: =IF(NOT(ISNUMBER(R2)),"",IF(U2="W",IF(ISNUMBER(P2),R2*(P2-1),""),IF(U2="L",-R2,IF(U2="Push",0,"")))) | X2: graded from final | Y2: N | Z2: https://x.com/BookitWithTrent/status/2083606714033578065 | AA2: "Last Chance U slip" | AB2: Parlay/multi-leg | AC2: =IF(ISNUMBER(V2),Q2,"") | AD2: =IF(ISNUMBER(W2),R2,"")
A3: T-134103 | B3: Trent | C3: 46236.508 | D3: =IF(C3="","",TEXT(C3,"dddd")) | E3: 46236 | F3: =IF(E3="","",TEXT(E3,"dddd")) | G3: not matched | H3: N | J3: Other | K3: PLL Lacrosse | L3: ML | M3: New York Atlas ML | N3: 1 | O3: not shown | R3: not shown | T3: not shown | U3: Unknown | V3: =IF(NOT(ISNUMBER(Q3)),"",IF(U3="W",IF(ISNUMBER(S3),S3-Q3,IF(ISNUMBER(P3),Q3*(P3-1),"")),IF(U3="L",-Q3,IF(U3="Push",0,"")))) | W3: =IF(NOT(ISNUMBER(R3)),"",IF(U3="W",IF(ISNUMBER(P3),R3*(P3-1),""),IF(U3="L",-R3,IF(U3="Push",0,"")))) | X3: unverified | Y3: N | Z3: https://x.com/BookitWithTrent/status/2083963819387134103 | AA3: "Mortal mega" (unit size not stated); Game date assumed = post date (CT) | AB3: Single | AC3: =IF(ISNUMBER(V3),Q3,"") | AD3: =IF(ISNUMBER(W3),R3,"")
A4: T-418015 | B4: Trent | C4: 46237.596 | D4: =IF(C4="","",TEXT(C4,"dddd")) | E4: 46237 | F4: =IF(E4="","",TEXT(E4,"dddd")) | G4: not matched | H4: N | J4: MLB | K4: MLB | L4: PrizePicks/DFS | M4: James Wood o7 HFS; Ben Rice o6.5 HFS; Jeremy Pena o7 HFS; Junior Caminero o9.5 HFS | N4: 4 | O4: not shown | P4: 10 | Q4: 500 | S4: 5000 | T4: PrizePicks | U4: L | V4: =IF(NOT(ISNUMBER(Q4)),"",IF(U4="W",IF(ISNUMBER(S4),S4-Q4,IF(ISNUMBER(P4),Q4*(P4-1),"")),IF(U4="L",-Q4,IF(U4="Push",0,"")))) | W4: =IF(NOT(ISNUMBER(R4)),"",IF(U4="W",IF(ISNUMBER(P4),R4*(P4-1),""),IF(U4="L",-R4,IF(U4="Push",0,"")))) | X4: graded from final | Y4: N | Z4: https://x.com/BookitWithTrent/status/2084358270215418015 | AA4: 4-pick power play; Final: Wood 1 single (3 HFS) < 7; Decimal odds derived from payout/stake | AB4: Parlay/multi-leg | AC4: =IF(ISNUMBER(V4),Q4,"") | AD4: =IF(ISNUMBER(W4),R4,"")
A5: T-128707 | B5: Trent | C5: 46237.952 | D5: =IF(C5="","",TEXT(C5,"dddd")) | E5: 46237 | F5: =IF(E5="","",TEXT(E5,"dddd")) | G5: 8:40 PM | H5: N | J5: MLB | K5: MLB | L5: parlay | M5: Brewers ML; Dodgers ML; Rays ML; Yankees ML | N5: 4 | O5: +800 | P5: 9 | Q5: 1000 | S5: 7000 | T5: Pikkit | U5: L | V5: =IF(NOT(ISNUMBER(Q5)),"",IF(U5="W",IF(ISNUMBER(S5),S5-Q5,IF(ISNUMBER(P5),Q5*(P5-1),"")),IF(U5="L",-Q5,IF(U5="Push",0,"")))) | W5: =IF(NOT(ISNUMBER(R5)),"",IF(U5="W",IF(ISNUMBER(P5),R5*(P5-1),""),IF(U5="L",-R5,IF(U5="Push",0,"")))) | X5: posted | Y5: N | Z5: https://x.com/BookitWithTrent/status/2084487077245128707 | AA5: "Fugazi Four"; slip shows +800 but payout $7,000; result slip shows 3 legs lost | AB5: Parlay/multi-leg | AC5: =IF(ISNUMBER(V5),Q5,"") | AD5: =IF(ISNUMBER(W5),R5,"")
A6: T-653770 | B6: Trent | C6: 46238.444 | D6: =IF(C6="","",TEXT(C6,"dddd")) | E6: 46238 | F6: =IF(E6="","",TEXT(E6,"dddd")) | G6: not matched | H6: N | J6: MLB | K6: MLB | L6: PrizePicks/DFS | M6: Jesus Luzardo o7.5 K; Tarik Skubal o7.5 K; Yordan Alvarez o6.5 HFS; Junior Caminero o2.5 H+R+RBI | N6: 4 | O6: not shown | P6: 10 | Q6: 1000 | S6: 10000 | T6: PrizePicks | U6: L | V6: =IF(NOT(ISNUMBER(Q6)),"",IF(U6="W",IF(ISNUMBER(S6),S6-Q6,IF(ISNUMBER(P6),Q6*(P6-1),"")),IF(U6="L",-Q6,IF(U6="Push",0,"")))) | W6: =IF(NOT(ISNUMBER(R6)),"",IF(U6="W",IF(ISNUMBER(P6),R6*(P6-1),""),IF(U6="L",-R6,IF(U6="Push",0,"")))) | X6: graded from final | Y6: N | Z6: https://x.com/BookitWithTrent/status/2084665349379653770 | AA6: Final: Luzardo 7 K, Skubal 6 K; Decimal odds derived from payout/stake | AB6: Parlay/multi-leg | AC6: =IF(ISNUMBER(V6),Q6,"") | AD6: =IF(ISNUMBER(W6),R6,"")
A7: T-732627 | B7: Trent | C7: 46238.475 | D7: =IF(C7="","",TEXT(C7,"dddd")) | E7: 46238 | F7: =IF(E7="","",TEXT(E7,"dddd")) | G7: not matched | H7: N | J7: MLB | K7: MLB | L7: PrizePicks/DFS | M7: Matt Olson HR; Shohei Ohtani HR; Yordan Alvarez HR; Junior Caminero HR (each o0.5) | N7: 4 | O7: not shown | P7: 82 | Q7: 250 | S7: 20500 | T7: PrizePicks | U7: L | V7: =IF(NOT(ISNUMBER(Q7)),"",IF(U7="W",IF(ISNUMBER(S7),S7-Q7,IF(ISNUMBER(P7),Q7*(P7-1),"")),IF(U7="L",-Q7,IF(U7="Push",0,"")))) | W7: =IF(NOT(ISNUMBER(R7)),"",IF(U7="W",IF(ISNUMBER(P7),R7*(P7-1),""),IF(U7="L",-R7,IF(U7="Push",0,"")))) | X7: graded from final | Y7: N | Z7: https://x.com/BookitWithTrent/status/2084676777360732627 | AA7: Final: Olson/Ohtani/Alvarez no HR; Decimal odds derived from payout/stake | AB7: Parlay/multi-leg | AC7: =IF(ISNUMBER(V7),Q7,"") | AD7: =IF(ISNUMBER(W7),R7,"")
A8: T-020893 | B8: Trent | C8: 46238.536 | D8: =IF(C8="","",TEXT(C8,"dddd")) | E8: 46238 | F8: =IF(E8="","",TEXT(E8,"dddd")) | G8: not matched | H8: N | J8: MLB | K8: MLB | L8: PrizePicks/DFS | M8: Trout o5.5 HFS; Rafaela o5.5 HFS; Baldwin o5.5 HFS; Freeman o5.5 HFS; Seager o5.5 HFS; Pena o5.5 HFS | N8: 6 | O8: not shown | P8: 37.5 | Q8: 500 | S8: 18750 | T8: PrizePicks | U8: L | V8: =IF(NOT(ISNUMBER(Q8)),"",IF(U8="W",IF(ISNUMBER(S8),S8-Q8,IF(ISNUMBER(P8),Q8*(P8-1),"")),IF(U8="L",-Q8,IF(U8="Push",0,"")))) | W8: =IF(NOT(ISNUMBER(R8)),"",IF(U8="W",IF(ISNUMBER(P8),R8*(P8-1),""),IF(U8="L",-R8,IF(U8="Push",0,"")))) | X8: graded from final | Y8: N | Z8: https://x.com/BookitWithTrent/status/2084698796060020893 | AA8: Final: Trout 3 HFS; Decimal odds derived from payout/stake | AB8: Parlay/multi-leg | AC8: =IF(ISNUMBER(V8),Q8,"") | AD8: =IF(ISNUMBER(W8),R8,"")
A9: T-991261 | B9: Trent | C9: 46238.587 | D9: =IF(C9="","",TEXT(C9,"dddd")) | E9: 46238 | F9: =IF(E9="","",TEXT(E9,"dddd")) | G9: 8:40 PM | H9: N | J9: MLB | K9: MLB | L9: parlay | M9: Phillies ML; Rays ML; Braves ML; Twins ML; Rangers ML | N9: 5 | O9: +900 | P9: 10 | Q9: 1000 | S9: 10000 | T9: Pikkit | U9: L | V9: =IF(NOT(ISNUMBER(Q9)),"",IF(U9="W",IF(ISNUMBER(S9),S9-Q9,IF(ISNUMBER(P9),Q9*(P9-1),"")),IF(U9="L",-Q9,IF(U9="Push",0,"")))) | W9: =IF(NOT(ISNUMBER(R9)),"",IF(U9="W",IF(ISNUMBER(P9),R9*(P9-1),""),IF(U9="L",-R9,IF(U9="Push",0,"")))) | X9: posted | Y9: N | Z9: https://x.com/BookitWithTrent/status/2084717205220991261 | AA9: "Fugazi Five"; result slip (105054) shows Twins leg lost | AB9: Parlay/multi-leg | AC9: =IF(ISNUMBER(V9),Q9,"") | AD9: =IF(ISNUMBER(W9),R9,"")
A10: T-959071 | B10: Trent | C10: 46239.425 | D10: =IF(C10="","",TEXT(C10,"dddd")) | E10: 46239 | F10: =IF(E10="","",TEXT(E10,"dddd")) | G10: not matched | H10: N | J10: MLB | K10: MLB | L10: PrizePicks/DFS | M10: Yordan Alvarez o6.5 HFS; Shohei Ohtani o6.5 HFS; Wyatt Langford o5.5 HFS; Junior Caminero o11.5 HFS | N10: 4 | O10: not shown | P10: 10 | Q10: 1000 | S10: 10000 | T10: PrizePicks | U10: W | V10: =IF(NOT(ISNUMBER(Q10)),"",IF(U10="W",IF(ISNUMBER(S10),S10-Q10,IF(ISNUMBER(P10),Q10*(P10-1),"")),IF(U10="L",-Q10,IF(U10="Push",0,"")))) | W10: =IF(NOT(ISNUMBER(R10)),"",IF(U10="W",IF(ISNUMBER(P10),R10*(P10-1),""),IF(U10="L",-R10,IF(U10="Push",0,"")))) | X10: posted | Y10: N | Z10: https://x.com/BookitWithTrent/status/2085021011854959071 | AA10: "Birthday 4 man nuke"; cashed per 416291/771254; Game date assumed = post date (CT); Decimal odds derived from payout/stake | AB10: Parlay/multi-leg | AC10: =IF(ISNUMBER(V10),Q10,"") | AD10: =IF(ISNUMBER(W10),R10,"")
A11: T-509092 | B11: Trent | C11: 46239.474 | D11: =IF(C11="","",TEXT(C11,"dddd")) | E11: 46239 | F11: =IF(E11="","",TEXT(E11,"dddd")) | G11: 2:20 PM | H11: N | J11: MLB | K11: MLB | L11: ML | M11: Dodgers ML | N11: 1 | O11: not shown | R11: 10 | T11: not shown | U11: L | V11: =IF(NOT(ISNUMBER(Q11)),"",IF(U11="W",IF(ISNUMBER(S11),S11-Q11,IF(ISNUMBER(P11),Q11*(P11-1),"")),IF(U11="L",-Q11,IF(U11="Push",0,"")))) | W11: =IF(NOT(ISNUMBER(R11)),"",IF(U11="W",IF(ISNUMBER(P11),R11*(P11-1),""),IF(U11="L",-R11,IF(U11="Push",0,"")))) | X11: graded from final | Y11: N | Z11: https://x.com/BookitWithTrent/status/2085038898317509092 | AA11: "10U Mortal Mega Max" (CHC vs LAD) | AB11: Single | AC11: =IF(ISNUMBER(V11),Q11,"") | AD11: =IF(ISNUMBER(W11),R11,"")
A12: T-070221 | B12: Trent | C12: 46239.495 | D12: =IF(C12="","",TEXT(C12,"dddd")) | E12: 46239 | F12: =IF(E12="","",TEXT(E12,"dddd")) | G12: not matched | H12: N | J12: MLB | K12: MLB | L12: PrizePicks/DFS | M12: Yordan Alvarez HR o0.5; Shohei Ohtani HR o0.5 | N12: 2 | O12: not shown | P12: 8 | Q12: 300 | S12: 2400 | T12: PrizePicks | U12: L | V12: =IF(NOT(ISNUMBER(Q12)),"",IF(U12="W",IF(ISNUMBER(S12),S12-Q12,IF(ISNUMBER(P12),Q12*(P12-1),"")),IF(U12="L",-Q12,IF(U12="Push",0,"")))) | W12: =IF(NOT(ISNUMBER(R12)),"",IF(U12="W",IF(ISNUMBER(P12),R12*(P12-1),""),IF(U12="L",-R12,IF(U12="Push",0,"")))) | X12: graded from final | Y12: N | Z12: https://x.com/BookitWithTrent/status/2085046247665070221 | AA12: Final: Alvarez no HR; Decimal odds derived from payout/stake | AB12: Parlay/multi-leg | AC12: =IF(ISNUMBER(V12),Q12,"") | AD12: =IF(ISNUMBER(W12),R12,"")
A13: T-678835 | B13: Trent | C13: 46239.654 | D13: =IF(C13="","",TEXT(C13,"dddd")) | E13: 46239 | F13: =IF(E13="","",TEXT(E13,"dddd")) | G13: not matched | H13: N | J13: MLB | K13: MLB | L13: PrizePicks/DFS | M13: Elly De La Cruz o7.5 HFS; Paul Skenes o7 K; Bobby Witt Jr. o6.5 HFS; Bryan Woo o35.5 PFS | N13: 4 | O13: not shown | P13: 10 | Q13: 2000 | S13: 20000 | T13: PrizePicks | U13: L | V13: =IF(NOT(ISNUMBER(Q13)),"",IF(U13="W",IF(ISNUMBER(S13),S13-Q13,IF(ISNUMBER(P13),Q13*(P13-1),"")),IF(U13="L",-Q13,IF(U13="Push",0,"")))) | W13: =IF(NOT(ISNUMBER(R13)),"",IF(U13="W",IF(ISNUMBER(P13),R13*(P13-1),""),IF(U13="L",-R13,IF(U13="Push",0,"")))) | X13: graded from final | Y13: N | Z13: https://x.com/BookitWithTrent/status/2085103959832678835 | AA13: late-night 4 man; Final: Skenes 6 K; Decimal odds derived from payout/stake | AB13: Parlay/multi-leg | AC13: =IF(ISNUMBER(V13),Q13,"") | AD13: =IF(ISNUMBER(W13),R13,"")
A14: T-006899 | B14: Trent | C14: 46239.693 | D14: =IF(C14="","",TEXT(C14,"dddd")) | E14: 46239 | F14: =IF(E14="","",TEXT(E14,"dddd")) | G14: 9:40 PM | H14: N | J14: MLB | K14: MLB | L14: parlay | M14: Braves ML; Phillies ML; Pirates ML; Mariners ML | N14: 4 | O14: +900 | P14: 10 | Q14: 1000 | S14: 10000 | T14: Pikkit | U14: L | V14: =IF(NOT(ISNUMBER(Q14)),"",IF(U14="W",IF(ISNUMBER(S14),S14-Q14,IF(ISNUMBER(P14),Q14*(P14-1),"")),IF(U14="L",-Q14,IF(U14="Push",0,"")))) | W14: =IF(NOT(ISNUMBER(R14)),"",IF(U14="W",IF(ISNUMBER(P14),R14*(P14-1),""),IF(U14="L",-R14,IF(U14="Push",0,"")))) | X14: graded from final | Y14: N | Z14: https://x.com/BookitWithTrent/status/2085118211373006899 | AA14: "Wednesday Night Fugazi" | AB14: Parlay/multi-leg | AC14: =IF(ISNUMBER(V14),Q14,"") | AD14: =IF(ISNUMBER(W14),R14,"")
A15: T-890696 | B15: Trent | C15: 46240.479 | D15: =IF(C15="","",TEXT(C15,"dddd")) | E15: 46240 | F15: =IF(E15="","",TEXT(E15,"dddd")) | G15: not matched | H15: N | J15: MLB | K15: MLB | L15: PrizePicks/DFS | M15: No-HR (u0.5 HR): De La Cruz; Cal Raleigh; Schwarber; Abreu; Olson; Caglianone | N15: 6 | O15: not shown | T15: PrizePicks | U15: L | V15: =IF(NOT(ISNUMBER(Q15)),"",IF(U15="W",IF(ISNUMBER(S15),S15-Q15,IF(ISNUMBER(P15),Q15*(P15-1),"")),IF(U15="L",-Q15,IF(U15="Push",0,"")))) | W15: =IF(NOT(ISNUMBER(R15)),"",IF(U15="W",IF(ISNUMBER(P15),R15*(P15-1),""),IF(U15="L",-R15,IF(U15="Push",0,"")))) | X15: graded from final | Y15: Y - tags PrizePicks | Z15: https://x.com/BookitWithTrent/status/2085403129818890696 | AA15: stake not shown (lineup screenshot); Final: De La Cruz homered | AB15: Parlay/multi-leg | AC15: =IF(ISNUMBER(V15),Q15,"") | AD15: =IF(ISNUMBER(W15),R15,"")
A16: T-785238 | B16: Trent | C16: 46240.492 | D16: =IF(C16="","",TEXT(C16,"dddd")) | E16: 46240 | F16: =IF(E16="","",TEXT(E16,"dddd")) | G16: not matched | H16: N | J16: MLB | K16: MLB | L16: PrizePicks/DFS | M16: Dylan Cease o39.5 PFS; Cristopher Sanchez o7 K; Ronald Acuna Jr. o6.5 HFS; Bobby Witt Jr. o6.5 HFS | N16: 4 | O16: not shown | P16: 10 | Q16: 1000 | S16: 10000 | T16: PrizePicks | U16: L | V16: =IF(NOT(ISNUMBER(Q16)),"",IF(U16="W",IF(ISNUMBER(S16),S16-Q16,IF(ISNUMBER(P16),Q16*(P16-1),"")),IF(U16="L",-Q16,IF(U16="Push",0,"")))) | W16: =IF(NOT(ISNUMBER(R16)),"",IF(U16="W",IF(ISNUMBER(P16),R16*(P16-1),""),IF(U16="L",-R16,IF(U16="Push",0,"")))) | X16: posted | Y16: N | Z16: https://x.com/BookitWithTrent/status/2085407541819785238 | AA16: Sanchez finished with 6 K (943495 "One fucking K"); Game date assumed = post date (CT); Decimal odds derived from payout/stake | AB16: Parlay/multi-leg | AC16: =IF(ISNUMBER(V16),Q16,"") | AD16: =IF(ISNUMBER(W16),R16,"")
A17: T-801235 | B17: Trent | C17: 46240.678 | D17: =IF(C17="","",TEXT(C17,"dddd")) | E17: 46240 | F17: =IF(E17="","",TEXT(E17,"dddd")) | G17: 8:00 PM | H17: Y | I17: TNF | J17: NFL | K17: NFL Preseason | L17: ML | M17: Arizona Cardinals ML (vs WAS) | N17: 1 | O17: +100 | P17: 2 | Q17: 1087.32 | R17: 10 | S17: 2132 | T17: PrizePicks | U17: L | V17: =IF(NOT(ISNUMBER(Q17)),"",IF(U17="W",IF(ISNUMBER(S17),S17-Q17,IF(ISNUMBER(P17),Q17*(P17-1),"")),IF(U17="L",-Q17,IF(U17="Push",0,"")))) | W17: =IF(NOT(ISNUMBER(R17)),"",IF(U17="W",IF(ISNUMBER(P17),R17*(P17-1),""),IF(U17="L",-R17,IF(U17="Push",0,"")))) | X17: posted | Y17: N | Z17: https://x.com/BookitWithTrent/status/2085475090179801235 | AA17: "Play of the Year" 10U; PrizePicks 1-pick slip $1,087.32 to win $2,132; loss stated in later post; Game date assumed = post date (CT) | AB17: Single | AC17: =IF(ISNUMBER(V17),Q17,"") | AD17: =IF(ISNUMBER(W17),R17,"")
A18: T-011621 | B18: Trent | C18: 46241.671 | D18: =IF(C18="","",TEXT(C18,"dddd")) | E18: 46241 | F18: =IF(E18="","",TEXT(E18,"dddd")) | G18: not matched | H18: N | J18: Other | K18: PLL Lacrosse | L18: ML | M18: Whipsnakes ML (vs Cannons) | N18: 1 | O18: not shown | R18: not shown | T18: not shown | U18: Unknown | V18: =IF(NOT(ISNUMBER(Q18)),"",IF(U18="W",IF(ISNUMBER(S18),S18-Q18,IF(ISNUMBER(P18),Q18*(P18-1),"")),IF(U18="L",-Q18,IF(U18="Push",0,"")))) | W18: =IF(NOT(ISNUMBER(R18)),"",IF(U18="W",IF(ISNUMBER(P18),R18*(P18-1),""),IF(U18="L",-R18,IF(U18="Push",0,"")))) | X18: unverified | Y18: N | Z18: https://x.com/BookitWithTrent/status/2085834923991011621 | AA18: "Mortal mega"; Game date assumed = post date (CT) | AB18: Single | AC18: =IF(ISNUMBER(V18),Q18,"") | AD18: =IF(ISNUMBER(W18),R18,"")
A19: T-053239 | B19: Trent | C19: 46242.43 | D19: =IF(C19="","",TEXT(C19,"dddd")) | E19: 46242 | F19: =IF(E19="","",TEXT(E19,"dddd")) | G19: 3:05 PM | H19: N | J19: MLB | K19: MLB | L19: parlay | M19: ATL ML -135; Chris Sale o6.5 K -668 | N19: 2 | O19: +100 | P19: 2 | Q19: 1000 | S19: 1000 | T19: Pikkit | U19: L | V19: =IF(NOT(ISNUMBER(Q19)),"",IF(U19="W",IF(ISNUMBER(S19),S19-Q19,IF(ISNUMBER(P19),Q19*(P19-1),"")),IF(U19="L",-Q19,IF(U19="Push",0,"")))) | W19: =IF(NOT(ISNUMBER(R19)),"",IF(U19="W",IF(ISNUMBER(P19),R19*(P19-1),""),IF(U19="L",-R19,IF(U19="Push",0,"")))) | X19: graded from final | Y19: Y - tags Pikkit | Z19: https://x.com/BookitWithTrent/status/2086110001551053239 | AA19: "Braves ML + Sale 7+"; payout field is to-win | AB19: Parlay/multi-leg | AC19: =IF(ISNUMBER(V19),Q19,"") | AD19: =IF(ISNUMBER(W19),R19,"")
A20: T-205609 | B20: Trent | C20: 46242.449 | D20: =IF(C20="","",TEXT(C20,"dddd")) | E20: 46242 | F20: =IF(E20="","",TEXT(E20,"dddd")) | G20: not matched | H20: N | J20: Other | K20: PLL Lacrosse | L20: spread | M20: New York Atlas +1.5 | N20: 1 | O20: not shown | T20: not shown | U20: Unknown | V20: =IF(NOT(ISNUMBER(Q20)),"",IF(U20="W",IF(ISNUMBER(S20),S20-Q20,IF(ISNUMBER(P20),Q20*(P20-1),"")),IF(U20="L",-Q20,IF(U20="Push",0,"")))) | W20: =IF(NOT(ISNUMBER(R20)),"",IF(U20="W",IF(ISNUMBER(P20),R20*(P20-1),""),IF(U20="L",-R20,IF(U20="Push",0,"")))) | X20: unverified | Y20: N | Z20: https://x.com/BookitWithTrent/status/2086116921108205609 | AA20: "Mortal mega" fading @krabs_bookit; Game date assumed = post date (CT) | AB20: Single | AC20: =IF(ISNUMBER(V20),Q20,"") | AD20: =IF(ISNUMBER(W20),R20,"")
A21: T-265862 | B21: Trent | C21: 46242.482 | D21: =IF(C21="","",TEXT(C21,"dddd")) | E21: 46242 | F21: =IF(E21="","",TEXT(E21,"dddd")) | G21: 3:05 PM | H21: N | J21: MLB | K21: MLB | L21: PrizePicks/DFS | M21: Under 0.5 HR: Ben Rice; Paul Goldschmidt; Trent Grisham; Austin Riley; Matt Olson; Mike Yastrzemski | N21: 6 | O21: +130 | P21: 2.3 | Q21: 2000 | S21: 2600 | T21: PrizePicks | U21: L | V21: =IF(NOT(ISNUMBER(Q21)),"",IF(U21="W",IF(ISNUMBER(S21),S21-Q21,IF(ISNUMBER(P21),Q21*(P21-1),"")),IF(U21="L",-Q21,IF(U21="Push",0,"")))) | W21: =IF(NOT(ISNUMBER(R21)),"",IF(U21="W",IF(ISNUMBER(P21),R21*(P21-1),""),IF(U21="L",-R21,IF(U21="Push",0,"")))) | X21: graded from final | Y21: Y - tags Pikkit | Z21: https://x.com/BookitWithTrent/status/2086128660709265862 | AA21: 2.3x power play shown on Pikkit; ATL@NYY no-HR lay; Final: Ben Rice homered | AB21: Parlay/multi-leg | AC21: =IF(ISNUMBER(V21),Q21,"") | AD21: =IF(ISNUMBER(W21),R21,"")
A22: T-455925 | B22: Trent | C22: 46243.438 | D22: =IF(C22="","",TEXT(C22,"dddd")) | E22: 46243 | F22: =IF(E22="","",TEXT(E22,"dddd")) | G22: not matched | H22: N | J22: MLB | K22: MLB | L22: PrizePicks/DFS | M22: CJ Abrams o6.5 HFS; Royce Lewis u5.5 HFS; Kumar Rocker u16.5 PO; Justin Wrobleski o27.5 PFS | N22: 4 | O22: not shown | P22: 10 | Q22: 1000 | S22: 10000 | T22: PrizePicks | U22: L | V22: =IF(NOT(ISNUMBER(Q22)),"",IF(U22="W",IF(ISNUMBER(S22),S22-Q22,IF(ISNUMBER(P22),Q22*(P22-1),"")),IF(U22="L",-Q22,IF(U22="Push",0,"")))) | W22: =IF(NOT(ISNUMBER(R22)),"",IF(U22="W",IF(ISNUMBER(P22),R22*(P22-1),""),IF(U22="L",-R22,IF(U22="Push",0,"")))) | X22: posted | Y22: N | Z22: https://x.com/BookitWithTrent/status/2086475207892455925 | AA22: Collab slip w/ @jovan_deeb; "I sold the 4 man"; Game date assumed = post date (CT); Decimal odds derived from payout/stake | AB22: Parlay/multi-leg | AC22: =IF(ISNUMBER(V22),Q22,"") | AD22: =IF(ISNUMBER(W22),R22,"")
A23: T-648430 | B23: Trent | C23: 46243.683 | D23: =IF(C23="","",TEXT(C23,"dddd")) | E23: 46243 | F23: =IF(E23="","",TEXT(E23,"dddd")) | G23: 8:20 PM | H23: N | J23: MLB | K23: MLB | L23: ML | M23: Houston Astros ML (Sunday night) | N23: 1 | O23: not shown | T23: not shown | U23: L | V23: =IF(NOT(ISNUMBER(Q23)),"",IF(U23="W",IF(ISNUMBER(S23),S23-Q23,IF(ISNUMBER(P23),Q23*(P23-1),"")),IF(U23="L",-Q23,IF(U23="Push",0,"")))) | W23: =IF(NOT(ISNUMBER(R23)),"",IF(U23="W",IF(ISNUMBER(P23),R23*(P23-1),""),IF(U23="L",-R23,IF(U23="Push",0,"")))) | X23: graded from final | Y23: N | Z23: https://x.com/BookitWithTrent/status/2086564147198648430 | AA23: "Sunday Night Mortal Mega... for all the coin back" | AB23: Single | AC23: =IF(ISNUMBER(V23),Q23,"") | AD23: =IF(ISNUMBER(W23),R23,"")
A24: T-372455 | B24: Trent | C24: 46244.561 | D24: =IF(C24="","",TEXT(C24,"dddd")) | E24: 46244 | F24: =IF(E24="","",TEXT(E24,"dddd")) | G24: not matched | H24: N | J24: MLB | K24: MLB | L24: PrizePicks/DFS | M24: Junior Caminero o8 HFS; Tarik Skubal o7.5 K | N24: 2 | O24: not shown | P24: 3 | Q24: 3000 | S24: 9000 | T24: PrizePicks | U24: L | V24: =IF(NOT(ISNUMBER(Q24)),"",IF(U24="W",IF(ISNUMBER(S24),S24-Q24,IF(ISNUMBER(P24),Q24*(P24-1),"")),IF(U24="L",-Q24,IF(U24="Push",0,"")))) | W24: =IF(NOT(ISNUMBER(R24)),"",IF(U24="W",IF(ISNUMBER(P24),R24*(P24-1),""),IF(U24="L",-R24,IF(U24="Push",0,"")))) | X24: posted | Y24: N | Z24: https://x.com/BookitWithTrent/status/2086882285014372455 | AA24: "worst 2 man ever gg"; Game date assumed = post date (CT); Decimal odds derived from payout/stake | AB24: Parlay/multi-leg | AC24: =IF(ISNUMBER(V24),Q24,"") | AD24: =IF(ISNUMBER(W24),R24,"")
A25: T-373509 | B25: Trent | C25: 46245.584 | D25: =IF(C25="","",TEXT(C25,"dddd")) | E25: 46245 | F25: =IF(E25="","",TEXT(E25,"dddd")) | G25: not matched | H25: N | J25: MLB | K25: MLB | L25: prop | M25: Blake Snell o14.5 1st-inning pitches (vs KC) | N25: 1 | O25: not shown | T25: PrizePicks | U25: L | V25: =IF(NOT(ISNUMBER(Q25)),"",IF(U25="W",IF(ISNUMBER(S25),S25-Q25,IF(ISNUMBER(P25),Q25*(P25-1),"")),IF(U25="L",-Q25,IF(U25="Push",0,"")))) | W25: =IF(NOT(ISNUMBER(R25)),"",IF(U25="W",IF(ISNUMBER(P25),R25*(P25-1),""),IF(U25="L",-R25,IF(U25="Push",0,"")))) | X25: posted | Y25: N | Z25: https://x.com/BookitWithTrent/status/2087252861994373509 | AA25: "Rare MLB Play of Year"; stake not shown; "worst fucking play ever"; Game date assumed = post date (CT) | AB25: Single | AC25: =IF(ISNUMBER(V25),Q25,"") | AD25: =IF(ISNUMBER(W25),R25,"")
A26: T-102203 | B26: Trent | C26: 46245.591 | D26: =IF(C26="","",TEXT(C26,"dddd")) | E26: 46245 | F26: =IF(E26="","",TEXT(E26,"dddd")) | G26: 10:10 PM | H26: N | J26: MLB | K26: MLB | L26: parlay | M26: Blue Jays ML; White Sox ML; Rangers ML; Astros ML; Dodgers ML | N26: 5 | O26: +1000 | P26: 11 | Q26: 1000 | S26: 11000 | T26: Pikkit | U26: L | V26: =IF(NOT(ISNUMBER(Q26)),"",IF(U26="W",IF(ISNUMBER(S26),S26-Q26,IF(ISNUMBER(P26),Q26*(P26-1),"")),IF(U26="L",-Q26,IF(U26="Push",0,"")))) | W26: =IF(NOT(ISNUMBER(R26)),"",IF(U26="W",IF(ISNUMBER(P26),R26*(P26-1),""),IF(U26="L",-R26,IF(U26="Push",0,"")))) | X26: graded from final | Y26: N | Z26: https://x.com/BookitWithTrent/status/2087255371677102203 | AA26: "Fugazi Five" | AB26: Parlay/multi-leg | AC26: =IF(ISNUMBER(V26),Q26,"") | AD26: =IF(ISNUMBER(W26),R26,"")
A27: T-155794 | B27: Trent | C27: 46245.605 | D27: =IF(C27="","",TEXT(C27,"dddd")) | E27: 46245 | F27: =IF(E27="","",TEXT(E27,"dddd")) | G27: 6:45 PM | H27: N | J27: MLB | K27: MLB | L27: card | M27: Cubs -1.5 | N27: 1 | O27: not shown | T27: not shown | U27: W | V27: =IF(NOT(ISNUMBER(Q27)),"",IF(U27="W",IF(ISNUMBER(S27),S27-Q27,IF(ISNUMBER(P27),Q27*(P27-1),"")),IF(U27="L",-Q27,IF(U27="Push",0,"")))) | W27: =IF(NOT(ISNUMBER(R27)),"",IF(U27="W",IF(ISNUMBER(P27),R27*(P27-1),""),IF(U27="L",-R27,IF(U27="Push",0,"")))) | X27: graded from final | Y27: N | Z27: https://x.com/BookitWithTrent/status/2087260715086155794 | AA27: Part of 8-pick "MLB Whales" card (each pick tracked as its own row) | AB27: Single | AC27: =IF(ISNUMBER(V27),Q27,"") | AD27: =IF(ISNUMBER(W27),R27,"")
A28: T-155794b | B28: Trent | C28: 46245.605 | D28: =IF(C28="","",TEXT(C28,"dddd")) | E28: 46245 | F28: =IF(E28="","",TEXT(E28,"dddd")) | G28: 9:45 PM | H28: N | J28: MLB | K28: MLB | L28: spread | M28: Astros -1.5 | N28: 1 | O28: not shown | T28: not shown | U28: L | V28: =IF(NOT(ISNUMBER(Q28)),"",IF(U28="W",IF(ISNUMBER(S28),S28-Q28,IF(ISNUMBER(P28),Q28*(P28-1),"")),IF(U28="L",-Q28,IF(U28="Push",0,"")))) | W28: =IF(NOT(ISNUMBER(R28)),"",IF(U28="W",IF(ISNUMBER(P28),R28*(P28-1),""),IF(U28="L",-R28,IF(U28="Push",0,"")))) | X28: graded from final | Y28: N | Z28: https://x.com/BookitWithTrent/status/2087260715086155794 | AA28: MLB Whales card | AB28: Single | AC28: =IF(ISNUMBER(V28),Q28,"") | AD28: =IF(ISNUMBER(W28),R28,"")
A29: T-155794c | B29: Trent | C29: 46245.605 | D29: =IF(C29="","",TEXT(C29,"dddd")) | E29: 46245 | F29: =IF(E29="","",TEXT(E29,"dddd")) | G29: 7:40 PM | H29: N | J29: MLB | K29: MLB | L29: spread | M29: White Sox F5 -0.5 | N29: 1 | O29: not shown | T29: not shown | U29: W | V29: =IF(NOT(ISNUMBER(Q29)),"",IF(U29="W",IF(ISNUMBER(S29),S29-Q29,IF(ISNUMBER(P29),Q29*(P29-1),"")),IF(U29="L",-Q29,IF(U29="Push",0,"")))) | W29: =IF(NOT(ISNUMBER(R29)),"",IF(U29="W",IF(ISNUMBER(P29),R29*(P29-1),""),IF(U29="L",-R29,IF(U29="Push",0,"")))) | X29: graded from final | Y29: N | Z29: https://x.com/BookitWithTrent/status/2087260715086155794 | AA29: MLB Whales card | AB29: Single | AC29: =IF(ISNUMBER(V29),Q29,"") | AD29: =IF(ISNUMBER(W29),R29,"")
A30: T-155794d | B30: Trent | C30: 46245.605 | D30: =IF(C30="","",TEXT(C30,"dddd")) | E30: 46245 | F30: =IF(E30="","",TEXT(E30,"dddd")) | G30: 9:38 PM | H30: N | J30: MLB | K30: MLB | L30: spread | M30: Rangers F5 -0.5 | N30: 1 | O30: not shown | T30: not shown | U30: L | V30: =IF(NOT(ISNUMBER(Q30)),"",IF(U30="W",IF(ISNUMBER(S30),S30-Q30,IF(ISNUMBER(P30),Q30*(P30-1),"")),IF(U30="L",-Q30,IF(U30="Push",0,"")))) | W30: =IF(NOT(ISNUMBER(R30)),"",IF(U30="W",IF(ISNUMBER(P30),R30*(P30-1),""),IF(U30="L",-R30,IF(U30="Push",0,"")))) | X30: graded from final | Y30: N | Z30: https://x.com/BookitWithTrent/status/2087260715086155794 | AA30: MLB Whales card | AB30: Single | AC30: =IF(ISNUMBER(V30),Q30,"") | AD30: =IF(ISNUMBER(W30),R30,"")
A31: T-155794e | B31: Trent | C31: 46245.605 | D31: =IF(C31="","",TEXT(C31,"dddd")) | E31: 46245 | F31: =IF(E31="","",TEXT(E31,"dddd")) | G31: 9:40 PM | H31: N | J31: MLB | K31: MLB | L31: total | M31: Dbacks/Rockies Over 9.5 | N31: 1 | O31: not shown | T31: not shown | U31: L | V31: =IF(NOT(ISNUMBER(Q31)),"",IF(U31="W",IF(ISNUMBER(S31),S31-Q31,IF(ISNUMBER(P31),Q31*(P31-1),"")),IF(U31="L",-Q31,IF(U31="Push",0,"")))) | W31: =IF(NOT(ISNUMBER(R31)),"",IF(U31="W",IF(ISNUMBER(P31),R31*(P31-1),""),IF(U31="L",-R31,IF(U31="Push",0,"")))) | X31: graded from final | Y31: N | Z31: https://x.com/BookitWithTrent/status/2087260715086155794 | AA31: MLB Whales card | AB31: Single | AC31: =IF(ISNUMBER(V31),Q31,"") | AD31: =IF(ISNUMBER(W31),R31,"")
A32: T-155794f | B32: Trent | C32: 46245.605 | D32: =IF(C32="","",TEXT(C32,"dddd")) | E32: 46245 | F32: =IF(E32="","",TEXT(E32,"dddd")) | G32: 7:40 PM | H32: N | J32: MLB | K32: MLB | L32: total | M32: Twins/Orioles Over 9.5 | N32: 1 | O32: not shown | T32: not shown | U32: L | V32: =IF(NOT(ISNUMBER(Q32)),"",IF(U32="W",IF(ISNUMBER(S32),S32-Q32,IF(ISNUMBER(P32),Q32*(P32-1),"")),IF(U32="L",-Q32,IF(U32="Push",0,"")))) | W32: =IF(NOT(ISNUMBER(R32)),"",IF(U32="W",IF(ISNUMBER(P32),R32*(P32-1),""),IF(U32="L",-R32,IF(U32="Push",0,"")))) | X32: graded from final | Y32: N | Z32: https://x.com/BookitWithTrent/status/2087260715086155794 | AA32: MLB Whales card | AB32: Single | AC32: =IF(ISNUMBER(V32),Q32,"") | AD32: =IF(ISNUMBER(W32),R32,"")
A33: T-155794g | B33: Trent | C33: 46245.605 | D33: =IF(C33="","",TEXT(C33,"dddd")) | E33: 46245 | F33: =IF(E33="","",TEXT(E33,"dddd")) | G33: 7:15 PM | H33: N | J33: MLB | K33: MLB | L33: total | M33: Mets/Braves Under 8.5 | N33: 1 | O33: not shown | T33: not shown | U33: W | V33: =IF(NOT(ISNUMBER(Q33)),"",IF(U33="W",IF(ISNUMBER(S33),S33-Q33,IF(ISNUMBER(P33),Q33*(P33-1),"")),IF(U33="L",-Q33,IF(U33="Push",0,"")))) | W33: =IF(NOT(ISNUMBER(R33)),"",IF(U33="W",IF(ISNUMBER(P33),R33*(P33-1),""),IF(U33="L",-R33,IF(U33="Push",0,"")))) | X33: graded from final | Y33: N | Z33: https://x.com/BookitWithTrent/status/2087260715086155794 | AA33: MLB Whales card | AB33: Single | AC33: =IF(ISNUMBER(V33),Q33,"") | AD33: =IF(ISNUMBER(W33),R33,"")
A34: T-155794h | B34: Trent | C34: 46245.605 | D34: =IF(C34="","",TEXT(C34,"dddd")) | E34: 46245 | F34: =IF(E34="","",TEXT(E34,"dddd")) | G34: 6:40 PM | H34: N | J34: MLB | K34: MLB | L34: total | M34: Guardians/Tigers Under 8.5 | N34: 1 | O34: not shown | T34: not shown | U34: L | V34: =IF(NOT(ISNUMBER(Q34)),"",IF(U34="W",IF(ISNUMBER(S34),S34-Q34,IF(ISNUMBER(P34),Q34*(P34-1),"")),IF(U34="L",-Q34,IF(U34="Push",0,"")))) | W34: =IF(NOT(ISNUMBER(R34)),"",IF(U34="W",IF(ISNUMBER(P34),R34*(P34-1),""),IF(U34="L",-R34,IF(U34="Push",0,"")))) | X34: graded from final | Y34: N | Z34: https://x.com/BookitWithTrent/status/2087260715086155794 | AA34: MLB Whales card | AB34: Single | AC34: =IF(ISNUMBER(V34),Q34,"") | AD34: =IF(ISNUMBER(W34),R34,"")
A35: T-412111 | B35: Trent | C35: 46246.492 | D35: =IF(C35="","",TEXT(C35,"dddd")) | E35: 46246 | F35: =IF(E35="","",TEXT(E35,"dddd")) | G35: 1:40 PM | H35: N | J35: MLB | K35: MLB | L35: ML | M35: Twins ML | N35: 1 | O35: -110 | P35: 1.9091 | T35: not shown | U35: W | V35: =IF(NOT(ISNUMBER(Q35)),"",IF(U35="W",IF(ISNUMBER(S35),S35-Q35,IF(ISNUMBER(P35),Q35*(P35-1),"")),IF(U35="L",-Q35,IF(U35="Push",0,"")))) | W35: =IF(NOT(ISNUMBER(R35)),"",IF(U35="W",IF(ISNUMBER(P35),R35*(P35-1),""),IF(U35="L",-R35,IF(U35="Push",0,"")))) | X35: graded from final | Y35: N | Z35: https://x.com/BookitWithTrent/status/2087581889888412111 | AA35: Daytime Baseball Megas card | AB35: Single | AC35: =IF(ISNUMBER(V35),Q35,"") | AD35: =IF(ISNUMBER(W35),R35,"")
A36: T-412111b | B36: Trent | C36: 46246.492 | D36: =IF(C36="","",TEXT(C36,"dddd")) | E36: 46246 | F36: =IF(E36="","",TEXT(E36,"dddd")) | G36: 2:15 PM | H36: N | J36: MLB | K36: MLB | L36: total | M36: Phillies/Cardinals Under 8 | N36: 1 | O36: -110 | P36: 1.9091 | T36: not shown | U36: Push | V36: =IF(NOT(ISNUMBER(Q36)),"",IF(U36="W",IF(ISNUMBER(S36),S36-Q36,IF(ISNUMBER(P36),Q36*(P36-1),"")),IF(U36="L",-Q36,IF(U36="Push",0,"")))) | W36: =IF(NOT(ISNUMBER(R36)),"",IF(U36="W",IF(ISNUMBER(P36),R36*(P36-1),""),IF(U36="L",-R36,IF(U36="Push",0,"")))) | X36: graded from final | Y36: N | Z36: https://x.com/BookitWithTrent/status/2087581889888412111 | AA36: Daytime Baseball Megas card | AB36: Single | AC36: =IF(ISNUMBER(V36),Q36,"") | AD36: =IF(ISNUMBER(W36),R36,"")
A37: T-412111c | B37: Trent | C37: 46246.492 | D37: =IF(C37="","",TEXT(C37,"dddd")) | E37: 46246 | F37: =IF(E37="","",TEXT(E37,"dddd")) | G37: 3:05 PM | H37: N | J37: MLB | K37: MLB | L37: spread | M37: Rays -1.5 | N37: 1 | O37: -130 | P37: 1.7692 | T37: not shown | U37: W | V37: =IF(NOT(ISNUMBER(Q37)),"",IF(U37="W",IF(ISNUMBER(S37),S37-Q37,IF(ISNUMBER(P37),Q37*(P37-1),"")),IF(U37="L",-Q37,IF(U37="Push",0,"")))) | W37: =IF(NOT(ISNUMBER(R37)),"",IF(U37="W",IF(ISNUMBER(P37),R37*(P37-1),""),IF(U37="L",-R37,IF(U37="Push",0,"")))) | X37: graded from final | Y37: N | Z37: https://x.com/BookitWithTrent/status/2087581889888412111 | AA37: Daytime Baseball Megas card | AB37: Single | AC37: =IF(ISNUMBER(V37),Q37,"") | AD37: =IF(ISNUMBER(W37),R37,"")
A38: T-412111d | B38: Trent | C38: 46246.492 | D38: =IF(C38="","",TEXT(C38,"dddd")) | E38: 46246 | F38: =IF(E38="","",TEXT(E38,"dddd")) | G38: 3:40 PM | H38: N | J38: MLB | K38: MLB | L38: total | M38: Rockies/Dbacks Over 9 | N38: 1 | O38: -110 | P38: 1.9091 | T38: not shown | U38: W | V38: =IF(NOT(ISNUMBER(Q38)),"",IF(U38="W",IF(ISNUMBER(S38),S38-Q38,IF(ISNUMBER(P38),Q38*(P38-1),"")),IF(U38="L",-Q38,IF(U38="Push",0,"")))) | W38: =IF(NOT(ISNUMBER(R38)),"",IF(U38="W",IF(ISNUMBER(P38),R38*(P38-1),""),IF(U38="L",-R38,IF(U38="Push",0,"")))) | X38: graded from final | Y38: N | Z38: https://x.com/BookitWithTrent/status/2087581889888412111 | AA38: Daytime Baseball Megas card | AB38: Single | AC38: =IF(ISNUMBER(V38),Q38,"") | AD38: =IF(ISNUMBER(W38),R38,"")
A39: T-283140 | B39: Trent | C39: 46246.844 | D39: =IF(C39="","",TEXT(C39,"dddd")) | E39: 46246 | F39: =IF(E39="","",TEXT(E39,"dddd")) | G39: 10:10 PM | H39: N | J39: MLB | K39: MLB | L39: spread | M39: Dodgers -1.5 | N39: 1 | O39: not shown | T39: not shown | U39: W | V39: =IF(NOT(ISNUMBER(Q39)),"",IF(U39="W",IF(ISNUMBER(S39),S39-Q39,IF(ISNUMBER(P39),Q39*(P39-1),"")),IF(U39="L",-Q39,IF(U39="Push",0,"")))) | W39: =IF(NOT(ISNUMBER(R39)),"",IF(U39="W",IF(ISNUMBER(P39),R39*(P39-1),""),IF(U39="L",-R39,IF(U39="Push",0,"")))) | X39: posted | Y39: N | Z39: https://x.com/BookitWithTrent/status/2087709718890283140 | AA39: "Mega max"; "AFTER 11 GAMES IT FINALLY CASHED" | AB39: Single | AC39: =IF(ISNUMBER(V39),Q39,"") | AD39: =IF(ISNUMBER(W39),R39,"")
A40: T-523783 | B40: Trent | C40: 46247.491 | D40: =IF(C40="","",TEXT(C40,"dddd")) | E40: 46247 | F40: =IF(E40="","",TEXT(E40,"dddd")) | G40: 1:10 PM | H40: N | J40: MLB | K40: MLB | L40: ML | M40: Pirates ML | N40: 1 | O40: not shown | T40: not shown | U40: W | V40: =IF(NOT(ISNUMBER(Q40)),"",IF(U40="W",IF(ISNUMBER(S40),S40-Q40,IF(ISNUMBER(P40),Q40*(P40-1),"")),IF(U40="L",-Q40,IF(U40="Push",0,"")))) | W40: =IF(NOT(ISNUMBER(R40)),"",IF(U40="W",IF(ISNUMBER(P40),R40*(P40-1),""),IF(U40="L",-R40,IF(U40="Push",0,"")))) | X40: posted | Y40: N | Z40: https://x.com/BookitWithTrent/status/2087944039148523783 | AA40: Daytime card; recap 116961 (4-1) | AB40: Single | AC40: =IF(ISNUMBER(V40),Q40,"") | AD40: =IF(ISNUMBER(W40),R40,"")
...

Sheet Summary
A1: Trent & Steve Bet Tracker — Summary (all formulas reference the Bets tab)
A2: CFB season start (Week 0): | C2: 46261 | D2: Thu Aug 27, 2026 (first FBS game Sat Aug 29, UNC vs TCU in Dublin)
A3: NFL season start (Week 1): | C3: 46274 | D3: Wed Sep 9, 2026 (Patriots at Seahawks)
A5: All bets (Aug 1, 2026 – present)
A6: Bettor | B6: Bets | C6: W | D6: L | E6: Push | F6: Pending | G6: Unknown | H6: Win % (W/(W+L)) | I6: Total staked $ (all $ bets) | J6: Settled staked $ | K6: Net P/L $ | L6: ROI (net / settled $) | M6: Units staked (settled) | N6: Net units | O6: ROI (units)
A7: Trent (@BookitWithTrent) | B7: =COUNTIFS(Bets!$A$2:$A$506,"<>",Bets!$B$2:$B$506,"Trent") | C7: =COUNTIFS(Bets!$A$2:$A$506,"<>",Bets!$B$2:$B$506,"Trent",Bets!$U$2:$U$506,"W") | D7: =COUNTIFS(Bets!$A$2:$A$506,"<>",Bets!$B$2:$B$506,"Trent",Bets!$U$2:$U$506,"L") | E7: =COUNTIFS(Bets!$A$2:$A$506,"<>",Bets!$B$2:$B$506,"Trent",Bets!$U$2:$U$506,"Push") | F7: =COUNTIFS(Bets!$A$2:$A$506,"<>",Bets!$B$2:$B$506,"Trent",Bets!$U$2:$U$506,"Pending") | G7: =COUNTIFS(Bets!$A$2:$A$506,"<>",Bets!$B$2:$B$506,"Trent",Bets!$U$2:$U$506,"Unknown") | H7: =IF(C7+D7=0,"",C7/(C7+D7)) | I7: =SUMIFS(Bets!$Q$2:$Q$506,Bets!$A$2:$A$506,"<>",Bets!$B$2:$B$506,"Trent") | J7: =SUMIFS(Bets!$AC$2:$AC$506,Bets!$A$2:$A$506,"<>",Bets!$B$2:$B$506,"Trent") | K7: =SUMIFS(Bets!$V$2:$V$506,Bets!$A$2:$A$506,"<>",Bets!$B$2:$B$506,"Trent") | L7: =IF(J7=0,"",K7/J7) | M7: =SUMIFS(Bets!$AD$2:$AD$506,Bets!$A$2:$A$506,"<>",Bets!$B$2:$B$506,"Trent") | N7: =SUMIFS(Bets!$W$2:$W$506,Bets!$A$2:$A$506,"<>",Bets!$B$2:$B$506,"Trent") | O7: =IF(M7=0,"",N7/M7)
A8: Steve (@stevewilldoit) | B8: =COUNTIFS(Bets!$A$2:$A$506,"<>",Bets!$B$2:$B$506,"Steve") | C8: =COUNTIFS(Bets!$A$2:$A$506,"<>",Bets!$B$2:$B$506,"Steve",Bets!$U$2:$U$506,"W") | D8: =COUNTIFS(Bets!$A$2:$A$506,"<>",Bets!$B$2:$B$506,"Steve",Bets!$U$2:$U$506,"L") | E8: =COUNTIFS(Bets!$A$2:$A$506,"<>",Bets!$B$2:$B$506,"Steve",Bets!$U$2:$U$506,"Push") | F8: =COUNTIFS(Bets!$A$2:$A$506,"<>",Bets!$B$2:$B$506,"Steve",Bets!$U$2:$U$506,"Pending") | G8: =COUNTIFS(Bets!$A$2:$A$506,"<>",Bets!$B$2:$B$506,"Steve",Bets!$U$2:$U$506,"Unknown") | H8: =IF(C8+D8=0,"",C8/(C8+D8)) | I8: =SUMIFS(Bets!$Q$2:$Q$506,Bets!$A$2:$A$506,"<>",Bets!$B$2:$B$506,"Steve") | J8: =SUMIFS(Bets!$AC$2:$AC$506,Bets!$A$2:$A$506,"<>",Bets!$B$2:$B$506,"Steve") | K8: =SUMIFS(Bets!$V$2:$V$506,Bets!$A$2:$A$506,"<>",Bets!$B$2:$B$506,"Steve") | L8: =IF(J8=0,"",K8/J8) | M8: =SUMIFS(Bets!$AD$2:$AD$506,Bets!$A$2:$A$506,"<>",Bets!$B$2:$B$506,"Steve") | N8: =SUMIFS(Bets!$W$2:$W$506,Bets!$A$2:$A$506,"<>",Bets!$B$2:$B$506,"Steve") | O8: =IF(M8=0,"",N8/M8)
A9: Combined | B9: =COUNTIFS(Bets!$A$2:$A$506,"<>",Bets!$B$2:$B$506,"*") | C9: =COUNTIFS(Bets!$A$2:$A$506,"<>",Bets!$B$2:$B$506,"*",Bets!$U$2:$U$506,"W") | D9: =COUNTIFS(Bets!$A$2:$A$506,"<>",Bets!$B$2:$B$506,"*",Bets!$U$2:$U$506,"L") | E9: =COUNTIFS(Bets!$A$2:$A$506,"<>",Bets!$B$2:$B$506,"*",Bets!$U$2:$U$506,"Push") | F9: =COUNTIFS(Bets!$A$2:$A$506,"<>",Bets!$B$2:$B$506,"*",Bets!$U$2:$U$506,"Pending") | G9: =COUNTIFS(Bets!$A$2:$A$506,"<>",Bets!$B$2:$B$506,"*",Bets!$U$2:$U$506,"Unknown") | H9: =IF(C9+D9=0,"",C9/(C9+D9)) | I9: =SUMIFS(Bets!$Q$2:$Q$506,Bets!$A$2:$A$506,"<>",Bets!$B$2:$B$506,"*") | J9: =SUMIFS(Bets!$AC$2:$AC$506,Bets!$A$2:$A$506,"<>",Bets!$B$2:$B$506,"*") | K9: =SUMIFS(Bets!$V$2:$V$506,Bets!$A$2:$A$506,"<>",Bets!$B$2:$B$506,"*") | L9: =IF(J9=0,"",K9/J9) | M9: =SUMIFS(Bets!$AD$2:$AD$506,Bets!$A$2:$A$506,"<>",Bets!$B$2:$B$506,"*") | N9: =SUMIFS(Bets!$W$2:$W$506,Bets!$A$2:$A$506,"<>",Bets!$B$2:$B$506,"*") | O9: =IF(M9=0,"",N9/M9)
A11: Since CFB start (game date ≥ C2)
A12: Bettor | B12: Bets | C12: W | D12: L | E12: Push | F12: Pending | G12: Unknown | H12: Win % (W/(W+L)) | I12: Total staked $ (all $ bets) | J12: Settled staked $ | K12: Net P/L $ | L12: ROI (net / settled $) | M12: Units staked (settled) | N12: Net units | O12: ROI (units)
A13: Trent (@BookitWithTrent) | B13: =COUNTIFS(Bets!$A$2:$A$506,"<>",Bets!$B$2:$B$506,"Trent",Bets!$E$2:$E$506,">="&$C$2) | C13: =COUNTIFS(Bets!$A$2:$A$506,"<>",Bets!$B$2:$B$506,"Trent",Bets!$E$2:$E$506,">="&$C$2,Bets!$U$2:$U$506,"W") | D13: =COUNTIFS(Bets!$A$2:$A$506,"<>",Bets!$B$2:$B$506,"Trent",Bets!$E$2:$E$506,">="&$C$2,Bets!$U$2:$U$506,"L") | E13: =COUNTIFS(Bets!$A$2:$A$506,"<>",Bets!$B$2:$B$506,"Trent",Bets!$E$2:$E$506,">="&$C$2,Bets!$U$2:$U$506,"Push") | F13: =COUNTIFS(Bets!$A$2:$A$506,"<>",Bets!$B$2:$B$506,"Trent",Bets!$E$2:$E$506,">="&$C$2,Bets!$U$2:$U$506,"Pending") | G13: =COUNTIFS(Bets!$A$2:$A$506,"<>",Bets!$B$2:$B$506,"Trent",Bets!$E$2:$E$506,">="&$C$2,Bets!$U$2:$U$506,"Unknown") | H13: =IF(C13+D13=0,"",C13/(C13+D13)) | I13: =SUMIFS(Bets!$Q$2:$Q$506,Bets!$A$2:$A$506,"<>",Bets!$B$2:$B$506,"Trent",Bets!$E$2:$E$506,">="&$C$2) | J13: =SUMIFS(Bets!$AC$2:$AC$506,Bets!$A$2:$A$506,"<>",Bets!$B$2:$B$506,"Trent",Bets!$E$2:$E$506,">="&$C$2) | K13: =SUMIFS(Bets!$V$2:$V$506,Bets!$A$2:$A$506,"<>",Bets!$B$2:$B$506,"Trent",Bets!$E$2:$E$506,">="&$C$2) | L13: =IF(J13=0,"",K13/J13) | M13: =SUMIFS(Bets!$AD$2:$AD$506,Bets!$A$2:$A$506,"<>",Bets!$B$2:$B$506,"Trent",Bets!$E$2:$E$506,">="&$C$2) | N13: =SUMIFS(Bets!$W$2:$W$506,Bets!$A$2:$A$506,"<>",Bets!$B$2:$B$506,"Trent",Bets!$E$2:$E$506,">="&$C$2) | O13: =IF(M13=0,"",N13/M13)
A14: Steve (@stevewilldoit) | B14: =COUNTIFS(Bets!$A$2:$A$506,"<>",Bets!$B$2:$B$506,"Steve",Bets!$E$2:$E$506,">="&$C$2) | C14: =COUNTIFS(Bets!$A$2:$A$506,"<>",Bets!$B$2:$B$506,"Steve",Bets!$E$2:$E$506,">="&$C$2,Bets!$U$2:$U$506,"W") | D14: =COUNTIFS(Bets!$A$2:$A$506,"<>",Bets!$B$2:$B$506,"Steve",Bets!$E$2:$E$506,">="&$C$2,Bets!$U$2:$U$506,"L") | E14: =COUNTIFS(Bets!$A$2:$A$506,"<>",Bets!$B$2:$B$506,"Steve",Bets!$E$2:$E$506,">="&$C$2,Bets!$U$2:$U$506,"Push") | F14: =COUNTIFS(Bets!$A$2:$A$506,"<>",Bets!$B$2:$B$506,"Steve",Bets!$E$2:$E$506,">="&$C$2,Bets!$U$2:$U$506,"Pending") | G14: =COUNTIFS(Bets!$A$2:$A$506,"<>",Bets!$B$2:$B$506,"Steve",Bets!$E$2:$E$506,">="&$C$2,Bets!$U$2:$U$506,"Unknown") | H14: =IF(C14+D14=0,"",C14/(C14+D14)) | I14: =SUMIFS(Bets!$Q$2:$Q$506,Bets!$A$2:$A$506,"<>",Bets!$B$2:$B$506,"Steve",Bets!$E$2:$E$506,">="&$C$2) | J14: =SUMIFS(Bets!$AC$2:$AC$506,Bets!$A$2:$A$506,"<>",Bets!$B$2:$B$506,"Steve",Bets!$E$2:$E$506,">="&$C$2) | K14: =SUMIFS(Bets!$V$2:$V$506,Bets!$A$2:$A$506,"<>",Bets!$B$2:$B$506,"Steve",Bets!$E$2:$E$506,">="&$C$2) | L14: =IF(J14=0,"",K14/J14) | M14: =SUMIFS(Bets!$AD$2:$AD$506,Bets!$A$2:$A$506,"<>",Bets!$B$2:$B$506,"Steve",Bets!$E$2:$E$506,">="&$C$2) | N14: =SUMIFS(Bets!$W$2:$W$506,Bets!$A$2:$A$506,"<>",Bets!$B$2:$B$506,"Steve",Bets!$E$2:$E$506,">="&$C$2) | O14: =IF(M14=0,"",N14/M14)
A15: Combined | B15: =COUNTIFS(Bets!$A$2:$A$506,"<>",Bets!$B$2:$B$506,"*",Bets!$E$2:$E$506,">="&$C$2) | C15: =COUNTIFS(Bets!$A$2:$A$506,"<>",Bets!$B$2:$B$506,"*",Bets!$E$2:$E$506,">="&$C$2,Bets!$U$2:$U$506,"W") | D15: =COUNTIFS(Bets!$A$2:$A$506,"<>",Bets!$B$2:$B$506,"*",Bets!$E$2:$E$506,">="&$C$2,Bets!$U$2:$U$506,"L") | E15: =COUNTIFS(Bets!$A$2:$A$506,"<>",Bets!$B$2:$B$506,"*",Bets!$E$2:$E$506,">="&$C$2,Bets!$U$2:$U$506,"Push") | F15: =COUNTIFS(Bets!$A$2:$A$506,"<>",Bets!$B$2:$B$506,"*",Bets!$E$2:$E$506,">="&$C$2,Bets!$U$2:$U$506,"Pending") | G15: =COUNTIFS(Bets!$A$2:$A$506,"<>",Bets!$B$2:$B$506,"*",Bets!$E$2:$E$506,">="&$C$2,Bets!$U$2:$U$506,"Unknown") | H15: =IF(C15+D15=0,"",C15/(C15+D15)) | I15: =SUMIFS(Bets!$Q$2:$Q$506,Bets!$A$2:$A$506,"<>",Bets!$B$2:$B$506,"*",Bets!$E$2:$E$506,">="&$C$2) | J15: =SUMIFS(Bets!$AC$2:$AC$506,Bets!$A$2:$A$506,"<>",Bets!$B$2:$B$506,"*",Bets!$E$2:$E$506,">="&$C$2) | K15: =SUMIFS(Bets!$V$2:$V$506,Bets!$A$2:$A$506,"<>",Bets!$B$2:$B$506,"*",Bets!$E$2:$E$506,">="&$C$2) | L15: =IF(J15=0,"",K15/J15) | M15: =SUMIFS(Bets!$AD$2:$AD$506,Bets!$A$2:$A$506,"<>",Bets!$B$2:$B$506,"*",Bets!$E$2:$E$506,">="&$C$2) | N15: =SUMIFS(Bets!$W$2:$W$506,Bets!$A$2:$A$506,"<>",Bets!$B$2:$B$506,"*",Bets!$E$2:$E$506,">="&$C$2) | O15: =IF(M15=0,"",N15/M15)
A17: Since NFL start (game date ≥ C3)
A18: Bettor | B18: Bets | C18: W | D18: L | E18: Push | F18: Pending | G18: Unknown | H18: Win % (W/(W+L)) | I18: Total staked $ (all $ bets) | J18: Settled staked $ | K18: Net P/L $ | L18: ROI (net / settled $) | M18: Units staked (settled) | N18: Net units | O18: ROI (units)
A19: Trent (@BookitWithTrent) | B19: =COUNTIFS(Bets!$A$2:$A$506,"<>",Bets!$B$2:$B$506,"Trent",Bets!$E$2:$E$506,">="&$C$3) | C19: =COUNTIFS(Bets!$A$2:$A$506,"<>",Bets!$B$2:$B$506,"Trent",Bets!$E$2:$E$506,">="&$C$3,Bets!$U$2:$U$506,"W") | D19: =COUNTIFS(Bets!$A$2:$A$506,"<>",Bets!$B$2:$B$506,"Trent",Bets!$E$2:$E$506,">="&$C$3,Bets!$U$2:$U$506,"L") | E19: =COUNTIFS(Bets!$A$2:$A$506,"<>",Bets!$B$2:$B$506,"Trent",Bets!$E$2:$E$506,">="&$C$3,Bets!$U$2:$U$506,"Push") | F19: =COUNTIFS(Bets!$A$2:$A$506,"<>",Bets!$B$2:$B$506,"Trent",Bets!$E$2:$E$506,">="&$C$3,Bets!$U$2:$U$506,"Pending") | G19: =COUNTIFS(Bets!$A$2:$A$506,"<>",Bets!$B$2:$B$506,"Trent",Bets!$E$2:$E$506,">="&$C$3,Bets!$U$2:$U$506,"Unknown") | H19: =IF(C19+D19=0,"",C19/(C19+D19)) | I19: =SUMIFS(Bets!$Q$2:$Q$506,Bets!$A$2:$A$506,"<>",Bets!$B$2:$B$506,"Trent",Bets!$E$2:$E$506,">="&$C$3) | J19: =SUMIFS(Bets!$AC$2:$AC$506,Bets!$A$2:$A$506,"<>",Bets!$B$2:$B$506,"Trent",Bets!$E$2:$E$506,">="&$C$3) | K19: =SUMIFS(Bets!$V$2:$V$506,Bets!$A$2:$A$506,"<>",Bets!$B$2:$B$506,"Trent",Bets!$E$2:$E$506,">="&$C$3) | L19: =IF(J19=0,"",K19/J19) | M19: =SUMIFS(Bets!$AD$2:$AD$506,Bets!$A$2:$A$506,"<>",Bets!$B$2:$B$506,"Trent",Bets!$E$2:$E$506,">="&$C$3) | N19: =SUMIFS(Bets!$W$2:$W$506,Bets!$A$2:$A$506,"<>",Bets!$B$2:$B$506,"Trent",Bets!$E$2:$E$506,">="&$C$3) | O19: =IF(M19=0,"",N19/M19)
A20: Steve (@stevewilldoit) | B20: =COUNTIFS(Bets!$A$2:$A$506,"<>",Bets!$B$2:$B$506,"Steve",Bets!$E$2:$E$506,">="&$C$3) | C20: =COUNTIFS(Bets!$A$2:$A$506,"<>",Bets!$B$2:$B$506,"Steve",Bets!$E$2:$E$506,">="&$C$3,Bets!$U$2:$U$506,"W") | D20: =COUNTIFS(Bets!$A$2:$A$506,"<>",Bets!$B$2:$B$506,"Steve",Bets!$E$2:$E$506,">="&$C$3,Bets!$U$2:$U$506,"L") | E20: =COUNTIFS(Bets!$A$2:$A$506,"<>",Bets!$B$2:$B$506,"Steve",Bets!$E$2:$E$506,">="&$C$3,Bets!$U$2:$U$506,"Push") | F20: =COUNTIFS(Bets!$A$2:$A$506,"<>",Bets!$B$2:$B$506,"Steve",Bets!$E$2:$E$506,">="&$C$3,Bets!$U$2:$U$506,"Pending") | G20: =COUNTIFS(Bets!$A$2:$A$506,"<>",Bets!$B$2:$B$506,"Steve",Bets!$E$2:$E$506,">="&$C$3,Bets!$U$2:$U$506,"Unknown") | H20: =IF(C20+D20=0,"",C20/(C20+D20)) | I20: =SUMIFS(Bets!$Q$2:$Q$506,Bets!$A$2:$A$506,"<>",Bets!$B$2:$B$506,"Steve",Bets!$E$2:$E$506,">="&$C$3) | J20: =SUMIFS(Bets!$AC$2:$AC$506,Bets!$A$2:$A$506,"<>",Bets!$B$2:$B$506,"Steve",Bets!$E$2:$E$506,">="&$C$3) | K20: =SUMIFS(Bets!$V$2:$V$506,Bets!$A$2:$A$506,"<>",Bets!$B$2:$B$506,"Steve",Bets!$E$2:$E$506,">="&$C$3) | L20: =IF(J20=0,"",K20/J20) | M20: =SUMIFS(Bets!$AD$2:$AD$506,Bets!$A$2:$A$506,"<>",Bets!$B$2:$B$506,"Steve",Bets!$E$2:$E$506,">="&$C$3) | N20: =SUMIFS(Bets!$W$2:$W$506,Bets!$A$2:$A$506,"<>",Bets!$B$2:$B$506,"Steve",Bets!$E$2:$E$506,">="&$C$3) | O20: =IF(M20=0,"",N20/M20)
A21: Combined | B21: =COUNTIFS(Bets!$A$2:$A$506,"<>",Bets!$B$2:$B$506,"*",Bets!$E$2:$E$506,">="&$C$3) | C21: =COUNTIFS(Bets!$A$2:$A$506,"<>",Bets!$B$2:$B$506,"*",Bets!$E$2:$E$506,">="&$C$3,Bets!$U$2:$U$506,"W") | D21: =COUNTIFS(Bets!$A$2:$A$506,"<>",Bets!$B$2:$B$506,"*",Bets!$E$2:$E$506,">="&$C$3,Bets!$U$2:$U$506,"L") | E21: =COUNTIFS(Bets!$A$2:$A$506,"<>",Bets!$B$2:$B$506,"*",Bets!$E$2:$E$506,">="&$C$3,Bets!$U$2:$U$506,"Push") | F21: =COUNTIFS(Bets!$A$2:$A$506,"<>",Bets!$B$2:$B$506,"*",Bets!$E$2:$E$506,">="&$C$3,Bets!$U$2:$U$506,"Pending") | G21: =COUNTIFS(Bets!$A$2:$A$506,"<>",Bets!$B$2:$B$506,"*",Bets!$E$2:$E$506,">="&$C$3,Bets!$U$2:$U$506,"Unknown") | H21: =IF(C21+D21=0,"",C21/(C21+D21)) | I21: =SUMIFS(Bets!$Q$2:$Q$506,Bets!$A$2:$A$506,"<>",Bets!$B$2:$B$506,"*",Bets!$E$2:$E$506,">="&$C$3) | J21: =SUMIFS(Bets!$AC$2:$AC$506,Bets!$A$2:$A$506,"<>",Bets!$B$2:$B$506,"*",Bets!$E$2:$E$506,">="&$C$3) | K21: =SUMIFS(Bets!$V$2:$V$506,Bets!$A$2:$A$506,"<>",Bets!$B$2:$B$506,"*",Bets!$E$2:$E$506,">="&$C$3) | L21: =IF(J21=0,"",K21/J21) | M21: =SUMIFS(Bets!$AD$2:$AD$506,Bets!$A$2:$A$506,"<>",Bets!$B$2:$B$506,"*",Bets!$E$2:$E$506,">="&$C$3) | N21: =SUMIFS(Bets!$W$2:$W$506,Bets!$A$2:$A$506,"<>",Bets!$B$2:$B$506,"*",Bets!$E$2:$E$506,">="&$C$3) | O21: =IF(M21=0,"",N21/M21)
A23: Football only (NFL + CFB), all dates
A24: Bettor | B24: Bets | C24: W | D24: L | E24: Push | F24: Pending | G24: Unknown | H24: Win % (W/(W+L)) | I24: Total staked $ (all $ bets) | J24: Settled staked $ | K24: Net P/L $ | L24: ROI (net / settled $) | M24: Units staked (settled) | N24: Net units | O24: ROI (units)
A25: Trent (@BookitWithTrent) | B25: =COUNTIFS(Bets!$A$2:$A$506,"<>",Bets!$B$2:$B$506,"Trent",Bets!$J$2:$J$506,"NFL") | C25: =COUNTIFS(Bets!$A$2:$A$506,"<>",Bets!$B$2:$B$506,"Trent",Bets!$J$2:$J$506,"NFL",Bets!$U$2:$U$506,"W") | D25: =COUNTIFS(Bets!$A$2:$A$506,"<>",Bets!$B$2:$B$506,"Trent",Bets!$J$2:$J$506,"NFL",Bets!$U$2:$U$506,"L") | E25: =COUNTIFS(Bets!$A$2:$A$506,"<>",Bets!$B$2:$B$506,"Trent",Bets!$J$2:$J$506,"NFL",Bets!$U$2:$U$506,"Push") | F25: =COUNTIFS(Bets!$A$2:$A$506,"<>",Bets!$B$2:$B$506,"Trent",Bets!$J$2:$J$506,"NFL",Bets!$U$2:$U$506,"Pending") | G25: =COUNTIFS(Bets!$A$2:$A$506,"<>",Bets!$B$2:$B$506,"Trent",Bets!$J$2:$J$506,"NFL",Bets!$U$2:$U$506,"Unknown") | H25: =IF(C25+D25=0,"",C25/(C25+D25)) | I25: =SUMIFS(Bets!$Q$2:$Q$506,Bets!$A$2:$A$506,"<>",Bets!$B$2:$B$506,"Trent",Bets!$J$2:$J$506,"NFL") | J25: =SUMIFS(Bets!$AC$2:$AC$506,Bets!$A$2:$A$506,"<>",Bets!$B$2:$B$506,"Trent",Bets!$J$2:$J$506,"NFL") | K25: =SUMIFS(Bets!$V$2:$V$506,Bets!$A$2:$A$506,"<>",Bets!$B$2:$B$506,"Trent",Bets!$J$2:$J$506,"NFL") | L25: =IF(J25=0,"",K25/J25) | M25: =SUMIFS(Bets!$AD$2:$AD$506,Bets!$A$2:$A$506,"<>",Bets!$B$2:$B$506,"Trent",Bets!$J$2:$J$506,"NFL") | N25: =SUMIFS(Bets!$W$2:$W$506,Bets!$A$2:$A$506,"<>",Bets!$B$2:$B$506,"Trent",Bets!$J$2:$J$506,"NFL") | O25: =IF(M25=0,"",N25/M25)
A26: Steve (@stevewilldoit) | B26: =COUNTIFS(Bets!$A$2:$A$506,"<>",Bets!$B$2:$B$506,"Steve",Bets!$J$2:$J$506,"NFL") | C26: =COUNTIFS(Bets!$A$2:$A$506,"<>",Bets!$B$2:$B$506,"Steve",Bets!$J$2:$J$506,"NFL",Bets!$U$2:$U$506,"W") | D26: =COUNTIFS(Bets!$A$2:$A$506,"<>",Bets!$B$2:$B$506,"Steve",Bets!$J$2:$J$506,"NFL",Bets!$U$2:$U$506,"L") | E26: =COUNTIFS(Bets!$A$2:$A$506,"<>",Bets!$B$2:$B$506,"Steve",Bets!$J$2:$J$506,"NFL",Bets!$U$2:$U$506,"Push") | F26: =COUNTIFS(Bets!$A$2:$A$506,"<>",Bets!$B$2:$B$506,"Steve",Bets!$J$2:$J$506,"NFL",Bets!$U$2:$U$506,"Pending") | G26: =COUNTIFS(Bets!$A$2:$A$506,"<>",Bets!$B$2:$B$506,"Steve",Bets!$J$2:$J$506,"NFL",Bets!$U$2:$U$506,"Unknown") | H26: =IF(C26+D26=0,"",C26/(C26+D26)) | I26: =SUMIFS(Bets!$Q$2:$Q$506,Bets!$A$2:$A$506,"<>",Bets!$B$2:$B$506,"Steve",Bets!$J$2:$J$506,"NFL") | J26: =SUMIFS(Bets!$AC$2:$AC$506,Bets!$A$2:$A$506,"<>",Bets!$B$2:$B$506,"Steve",Bets!$J$2:$J$506,"NFL") | K26: =SUMIFS(Bets!$V$2:$V$506,Bets!$A$2:$A$506,"<>",Bets!$B$2:$B$506,"Steve",Bets!$J$2:$J$506,"NFL") | L26: =IF(J26=0,"",K26/J26) | M26: =SUMIFS(Bets!$AD$2:$AD$506,Bets!$A$2:$A$506,"<>",Bets!$B$2:$B$506,"Steve",Bets!$J$2:$J$506,"NFL") | N26: =SUMIFS(Bets!$W$2:$W$506,Bets!$A$2:$A$506,"<>",Bets!$B$2:$B$506,"Steve",Bets!$J$2:$J$506,"NFL") | O26: =IF(M26=0,"",N26/M26)
A27: Combined | B27: =COUNTIFS(Bets!$A$2:$A$506,"<>",Bets!$B$2:$B$506,"*",Bets!$J$2:$J$506,"NFL") | C27: =COUNTIFS(Bets!$A$2:$A$506,"<>",Bets!$B$2:$B$506,"*",Bets!$J$2:$J$506,"NFL",Bets!$U$2:$U$506,"W") | D27: =COUNTIFS(Bets!$A$2:$A$506,"<>",Bets!$B$2:$B$506,"*",Bets!$J$2:$J$506,"NFL",Bets!$U$2:$U$506,"L") | E27: =COUNTIFS(Bets!$A$2:$A$506,"<>",Bets!$B$2:$B$506,"*",Bets!$J$2:$J$506,"NFL",Bets!$U$2:$U$506,"Push") | F27: =COUNTIFS(Bets!$A$2:$A$506,"<>",Bets!$B$2:$B$506,"*",Bets!$J$2:$J$506,"NFL",Bets!$U$2:$U$506,"Pending") | G27: =COUNTIFS(Bets!$A$2:$A$506,"<>",Bets!$B$2:$B$506,"*",Bets!$J$2:$J$506,"NFL",Bets!$U$2:$U$506,"Unknown") | H27: =IF(C27+D27=0,"",C27/(C27+D27)) | I27: =SUMIFS(Bets!$Q$2:$Q$506,Bets!$A$2:$A$506,"<>",Bets!$B$2:$B$506,"*",Bets!$J$2:$J$506,"NFL") | J27: =SUMIFS(Bets!$AC$2:$AC$506,Bets!$A$2:$A$506,"<>",Bets!$B$2:$B$506,"*",Bets!$J$2:$J$506,"NFL") | K27: =SUMIFS(Bets!$V$2:$V$506,Bets!$A$2:$A$506,"<>",Bets!$B$2:$B$506,"*",Bets!$J$2:$J$506,"NFL") | L27: =IF(J27=0,"",K27/J27) | M27: =SUMIFS(Bets!$AD$2:$AD$506,Bets!$A$2:$A$506,"<>",Bets!$B$2:$B$506,"*",Bets!$J$2:$J$506,"NFL") | N27: =SUMIFS(Bets!$W$2:$W$506,Bets!$A$2:$A$506,"<>",Bets!$B$2:$B$506,"*",Bets!$J$2:$J$506,"NFL") | O27: =IF(M27=0,"",N27/M27)
A28: Trent (@BookitWithTrent) – CFB | B28: =COUNTIFS(Bets!$A$2:$A$506,"<>",Bets!$B$2:$B$506,"Trent",Bets!$J$2:$J$506,"CFB") | C28: =COUNTIFS(Bets!$A$2:$A$506,"<>",Bets!$B$2:$B$506,"Trent",Bets!$J$2:$J$506,"CFB",Bets!$U$2:$U$506,"W") | D28: =COUNTIFS(Bets!$A$2:$A$506,"<>",Bets!$B$2:$B$506,"Trent",Bets!$J$2:$J$506,"CFB",Bets!$U$2:$U$506,"L") | E28: =COUNTIFS(Bets!$A$2:$A$506,"<>",Bets!$B$2:$B$506,"Trent",Bets!$J$2:$J$506,"CFB",Bets!$U$2:$U$506,"Push") | F28: =COUNTIFS(Bets!$A$2:$A$506,"<>",Bets!$B$2:$B$506,"Trent",Bets!$J$2:$J$506,"CFB",Bets!$U$2:$U$506,"Pending") | G28: =COUNTIFS(Bets!$A$2:$A$506,"<>",Bets!$B$2:$B$506,"Trent",Bets!$J$2:$J$506,"CFB",Bets!$U$2:$U$506,"Unknown") | H28: =IF(C28+D28=0,"",C28/(C28+D28)) | I28: =SUMIFS(Bets!$Q$2:$Q$506,Bets!$A$2:$A$506,"<>",Bets!$B$2:$B$506,"Trent",Bets!$J$2:$J$506,"CFB") | J28: =SUMIFS(Bets!$AC$2:$AC$506,Bets!$A$2:$A$506,"<>",Bets!$B$2:$B$506,"Trent",Bets!$J$2:$J$506,"CFB") | K28: =SUMIFS(Bets!$V$2:$V$506,Bets!$A$2:$A$506,"<>",Bets!$B$2:$B$506,"Trent",Bets!$J$2:$J$506,"CFB") | L28: =IF(J28=0,"",K28/J28) | M28: =SUMIFS(Bets!$AD$2:$AD$506,Bets!$A$2:$A$506,"<>",Bets!$B$2:$B$506,"Trent",Bets!$J$2:$J$506,"CFB") | N28: =SUMIFS(Bets!$W$2:$W$506,Bets!$A$2:$A$506,"<>",Bets!$B$2:$B$506,"Trent",Bets!$J$2:$J$506,"CFB") | O28: =IF(M28=0,"",N28/M28)
A29: Steve (@stevewilldoit) – CFB | B29: =COUNTIFS(Bets!$A$2:$A$506,"<>",Bets!$B$2:$B$506,"Steve",Bets!$J$2:$J$506,"CFB") | C29: =COUNTIFS(Bets!$A$2:$A$506,"<>",Bets!$B$2:$B$506,"Steve",Bets!$J$2:$J$506,"CFB",Bets!$U$2:$U$506,"W") | D29: =COUNTIFS(Bets!$A$2:$A$506,"<>",Bets!$B$2:$B$506,"Steve",Bets!$J$2:$J$506,"CFB",Bets!$U$2:$U$506,"L") | E29: =COUNTIFS(Bets!$A$2:$A$506,"<>",Bets!$B$2:$B$506,"Steve",Bets!$J$2:$J$506,"CFB",Bets!$U$2:$U$506,"Push") | F29: =COUNTIFS(Bets!$A$2:$A$506,"<>",Bets!$B$2:$B$506,"Steve",Bets!$J$2:$J$506,"CFB",Bets!$U$2:$U$506,"Pending") | G29: =COUNTIFS(Bets!$A$2:$A$506,"<>",Bets!$B$2:$B$506,"Steve",Bets!$J$2:$J$506,"CFB",Bets!$U$2:$U$506,"Unknown") | H29: =IF(C29+D29=0,"",C29/(C29+D29)) | I29: =SUMIFS(Bets!$Q$2:$Q$506,Bets!$A$2:$A$506,"<>",Bets!$B$2:$B$506,"Steve",Bets!$J$2:$J$506,"CFB") | J29: =SUMIFS(Bets!$AC$2:$AC$506,Bets!$A$2:$A$506,"<>",Bets!$B$2:$B$506,"Steve",Bets!$J$2:$J$506,"CFB") | K29: =SUMIFS(Bets!$V$2:$V$506,Bets!$A$2:$A$506,"<>",Bets!$B$2:$B$506,"Steve",Bets!$J$2:$J$506,"CFB") | L29: =IF(J29=0,"",K29/J29) | M29: =SUMIFS(Bets!$AD$2:$AD$506,Bets!$A$2:$A$506,"<>",Bets!$B$2:$B$506,"Steve",Bets!$J$2:$J$506,"CFB") | N29: =SUMIFS(Bets!$W$2:$W$506,Bets!$A$2:$A$506,"<>",Bets!$B$2:$B$506,"Steve",Bets!$J$2:$J$506,"CFB") | O29: =IF(M29=0,"",N29/M29)
A30: Combined – CFB | B30: =COUNTIFS(Bets!$A$2:$A$506,"<>",Bets!$B$2:$B$506,"*",Bets!$J$2:$J$506,"CFB") | C30: =COUNTIFS(Bets!$A$2:$A$506,"<>",Bets!$B$2:$B$506,"*",Bets!$J$2:$J$506,"CFB",Bets!$U$2:$U$506,"W") | D30: =COUNTIFS(Bets!$A$2:$A$506,"<>",Bets!$B$2:$B$506,"*",Bets!$J$2:$J$506,"CFB",Bets!$U$2:$U$506,"L") | E30: =COUNTIFS(Bets!$A$2:$A$506,"<>",Bets!$B$2:$B$506,"*",Bets!$J$2:$J$506,"CFB",Bets!$U$2:$U$506,"Push") | F30: =COUNTIFS(Bets!$A$2:$A$506,"<>",Bets!$B$2:$B$506,"*",Bets!$J$2:$J$506,"CFB",Bets!$U$2:$U$506,"Pending") | G30: =COUNTIFS(Bets!$A$2:$A$506,"<>",Bets!$B$2:$B$506,"*",Bets!$J$2:$J$506,"CFB",Bets!$U$2:$U$506,"Unknown") | H30: =IF(C30+D30=0,"",C30/(C30+D30)) | I30: =SUMIFS(Bets!$Q$2:$Q$506,Bets!$A$2:$A$506,"<>",Bets!$B$2:$B$506,"*",Bets!$J$2:$J$506,"CFB") | J30: =SUMIFS(Bets!$AC$2:$AC$506,Bets!$A$2:$A$506,"<>",Bets!$B$2:$B$506,"*",Bets!$J$2:$J$506,"CFB") | K30: =SUMIFS(Bets!$V$2:$V$506,Bets!$A$2:$A$506,"<>",Bets!$B$2:$B$506,"*",Bets!$J$2:$J$506,"CFB") | L30: =IF(J30=0,"",K30/J30) | M30: =SUMIFS(Bets!$AD$2:$AD$506,Bets!$A$2:$A$506,"<>",Bets!$B$2:$B$506,"*",Bets!$J$2:$J$506,"CFB") | N30: =SUMIFS(Bets!$W$2:$W$506,Bets!$A$2:$A$506,"<>",Bets!$B$2:$B$506,"*",Bets!$J$2:$J$506,"CFB") | O30: =IF(M30=0,"",N30/M30)

Sheet By Sport
A1: Record / staked / P&L / ROI by sport category
A3: Trent (@BookitWithTrent)
A4: Bettor | B4: Sport | C4: Bets | D4: W | E4: L | F4: Push | G4: Pending | H4: Unknown | I4: Win % (W/(W+L)) | J4: Total staked $ (all $ bets) | K4: Settled staked $ | L4: Net P/L $ | M4: ROI (net / settled $) | N4: Units staked (settled) | O4: Net units | P4: ROI (units)
A5: Trent (@BookitWithTrent) | B5: CFB | C5: =COUNTIFS(Bets!$A$2:$A$506,"<>",Bets!$B$2:$B$506,"Trent",Bets!$J$2:$J$506,"CFB") | D5: =COUNTIFS(Bets!$A$2:$A$506,"<>",Bets!$B$2:$B$506,"Trent",Bets!$J$2:$J$506,"CFB",Bets!$U$2:$U$506,"W") | E5: =COUNTIFS(Bets!$A$2:$A$506,"<>",Bets!$B$2:$B$506,"Trent",Bets!$J$2:$J$506,"CFB",Bets!$U$2:$U$506,"L") | F5: =COUNTIFS(Bets!$A$2:$A$506,"<>",Bets!$B$2:$B$506,"Trent",Bets!$J$2:$J$506,"CFB",Bets!$U$2:$U$506,"Push") | G5: =COUNTIFS(Bets!$A$2:$A$506,"<>",Bets!$B$2:$B$506,"Trent",Bets!$J$2:$J$506,"CFB",Bets!$U$2:$U$506,"Pending") | H5: =COUNTIFS(Bets!$A$2:$A$506,"<>",Bets!$B$2:$B$506,"Trent",Bets!$J$2:$J$506,"CFB",Bets!$U$2:$U$506,"Unknown") | I5: =IF(D5+E5=0,"",D5/(D5+E5)) | J5: =SUMIFS(Bets!$Q$2:$Q$506,Bets!$A$2:$A$506,"<>",Bets!$B$2:$B$506,"Trent",Bets!$J$2:$J$506,"CFB") | K5: =SUMIFS(Bets!$AC$2:$AC$506,Bets!$A$2:$A$506,"<>",Bets!$B$2:$B$506,"Trent",Bets!$J$2:$J$506,"CFB") | L5: =SUMIFS(Bets!$V$2:$V$506,Bets!$A$2:$A$506,"<>",Bets!$B$2:$B$506,"Trent",Bets!$J$2:$J$506,"CFB") | M5: =IF(K5=0,"",L5/K5) | N5: =SUMIFS(Bets!$AD$2:$AD$506,Bets!$A$2:$A$506,"<>",Bets!$B$2:$B$506,"Trent",Bets!$J$2:$J$506,"CFB") | O5: =SUMIFS(Bets!$W$2:$W$506,Bets!$A$2:$A$506,"<>",Bets!$B$2:$B$506,"Trent",Bets!$J$2:$J$506,"CFB") | P5: =IF(N5=0,"",O5/N5)
A6: Trent (@BookitWithTrent) | B6: MLB | C6: =COUNTIFS(Bets!$A$2:$A$506,"<>",Bets!$B$2:$B$506,"Trent",Bets!$J$2:$J$506,"MLB") | D6: =COUNTIFS(Bets!$A$2:$A$506,"<>",Bets!$B$2:$B$506,"Trent",Bets!$J$2:$J$506,"MLB",Bets!$U$2:$U$506,"W") | E6: =COUNTIFS(Bets!$A$2:$A$506,"<>",Bets!$B$2:$B$506,"Trent",Bets!$J$2:$J$506,"MLB",Bets!$U$2:$U$506,"L") | F6: =COUNTIFS(Bets!$A$2:$A$506,"<>",Bets!$B$2:$B$506,"Trent",Bets!$J$2:$J$506,"MLB",Bets!$U$2:$U$506,"Push") | G6: =COUNTIFS(Bets!$A$2:$A$506,"<>",Bets!$B$2:$B$506,"Trent",Bets!$J$2:$J$506,"MLB",Bets!$U$2:$U$506,"Pending") | H6: =COUNTIFS(Bets!$A$2:$A$506,"<>",Bets!$B$2:$B$506,"Trent",Bets!$J$2:$J$506,"MLB",Bets!$U$2:$U$506,"Unknown") | I6: =IF(D6+E6=0,"",D6/(D6+E6)) | J6: =SUMIFS(Bets!$Q$2:$Q$506,Bets!$A$2:$A$506,"<>",Bets!$B$2:$B$506,"Trent",Bets!$J$2:$J$506,"MLB") | K6: =SUMIFS(Bets!$AC$2:$AC$506,Bets!$A$2:$A$506,"<>",Bets!$B$2:$B$506,"Trent",Bets!$J$2:$J$506,"MLB") | L6: =SUMIFS(Bets!$V$2:$V$506,Bets!$A$2:$A$506,"<>",Bets!$B$2:$B$506,"Trent",Bets!$J$2:$J$506,"MLB") | M6: =IF(K6=0,"",L6/K6) | N6: =SUMIFS(Bets!$AD$2:$AD$506,Bets!$A$2:$A$506,"<>",Bets!$B$2:$B$506,"Trent",Bets!$J$2:$J$506,"MLB") | O6: =SUMIFS(Bets!$W$2:$W$506,Bets!$A$2:$A$506,"<>",Bets!$B$2:$B$506,"Trent",Bets!$J$2:$J$506,"MLB") | P6: =IF(N6=0,"",O6/N6)
A7: Trent (@BookitWithTrent) | B7: NFL | C7: =COUNTIFS(Bets!$A$2:$A$506,"<>",Bets!$B$2:$B$506,"Trent",Bets!$J$2:$J$506,"NFL") | D7: =COUNTIFS(Bets!$A$2:$A$506,"<>",Bets!$B$2:$B$506,"Trent",Bets!$J$2:$J$506,"NFL",Bets!$U$2:$U$506,"W") | E7: =COUNTIFS(Bets!$A$2:$A$506,"<>",Bets!$B$2:$B$506,"Trent",Bets!$J$2:$J$506,"NFL",Bets!$U$2:$U$506,"L") | F7: =COUNTIFS(Bets!$A$2:$A$506,"<>",Bets!$B$2:$B$506,"Trent",Bets!$J$2:$J$506,"NFL",Bets!$U$2:$U$506,"Push") | G7: =COUNTIFS(Bets!$A$2:$A$506,"<>",Bets!$B$2:$B$506,"Trent",Bets!$J$2:$J$506,"NFL",Bets!$U$2:$U$506,"Pending") | H7: =COUNTIFS(Bets!$A$2:$A$506,"<>",Bets!$B$2:$B$506,"Trent",Bets!$J$2:$J$506,"NFL",Bets!$U$2:$U$506,"Unknown") | I7: =IF(D7+E7=0,"",D7/(D7+E7)) | J7: =SUMIFS(Bets!$Q$2:$Q$506,Bets!$A$2:$A$506,"<>",Bets!$B$2:$B$506,"Trent",Bets!$J$2:$J$506,"NFL") | K7: =SUMIFS(Bets!$AC$2:$AC$506,Bets!$A$2:$A$506,"<>",Bets!$B$2:$B$506,"Trent",Bets!$J$2:$J$506,"NFL") | L7: =SUMIFS(Bets!$V$2:$V$506,Bets!$A$2:$A$506,"<>",Bets!$B$2:$B$506,"Trent",Bets!$J$2:$J$506,"NFL") | M7: =IF(K7=0,"",L7/K7) | N7: =SUMIFS(Bets!$AD$2:$AD$506,Bets!$A$2:$A$506,"<>",Bets!$B$2:$B$506,"Trent",Bets!$J$2:$J$506,"NFL") | O7: =SUMIFS(Bets!$W$2:$W$506,Bets!$A$2:$A$506,"<>",Bets!$B$2:$B$506,"Trent",Bets!$J$2:$J$506,"NFL") | P7: =IF(N7=0,"",O7/N7)
A8: Trent (@BookitWithTrent) | B8: Other | C8: =COUNTIFS(Bets!$A$2:$A$506,"<>",Bets!$B$2:$B$506,"Trent",Bets!$J$2:$J$506,"Other") | D8: =COUNTIFS(Bets!$A$2:$A$506,"<>",Bets!$B$2:$B$506,"Trent",Bets!$J$2:$J$506,"Other",Bets!$U$2:$U$506,"W") | E8: =COUNTIFS(Bets!$A$2:$A$506,"<>",Bets!$B$2:$B$506,"Trent",Bets!$J$2:$J$506,"Other",Bets!$U$2:$U$506,"L") | F8: =COUNTIFS(Bets!$A$2:$A$506,"<>",Bets!$B$2:$B$506,"Trent",Bets!$J$2:$J$506,"Other",Bets!$U$2:$U$506,"Push") | G8: =COUNTIFS(Bets!$A$2:$A$506,"<>",Bets!$B$2:$B$506,"Trent",Bets!$J$2:$J$506,"Other",Bets!$U$2:$U$506,"Pending") | H8: =COUNTIFS(Bets!$A$2:$A$506,"<>",Bets!$B$2:$B$506,"Trent",Bets!$J$2:$J$506,"Other",Bets!$U$2:$U$506,"Unknown") | I8: =IF(D8+E8=0,"",D8/(D8+E8)) | J8: =SUMIFS(Bets!$Q$2:$Q$506,Bets!$A$2:$A$506,"<>",Bets!$B$2:$B$506,"Trent",Bets!$J$2:$J$506,"Other") | K8: =SUMIFS(Bets!$AC$2:$AC$506,Bets!$A$2:$A$506,"<>",Bets!$B$2:$B$506,"Trent",Bets!$J$2:$J$506,"Other") | L8: =SUMIFS(Bets!$V$2:$V$506,Bets!$A$2:$A$506,"<>",Bets!$B$2:$B$506,"Trent",Bets!$J$2:$J$506,"Other") | M8: =IF(K8=0,"",L8/K8) | N8: =SUMIFS(Bets!$AD$2:$AD$506,Bets!$A$2:$A$506,"<>",Bets!$B$2:$B$506,"Trent",Bets!$J$2:$J$506,"Other") | O8: =SUMIFS(Bets!$W$2:$W$506,Bets!$A$2:$A$506,"<>",Bets!$B$2:$B$506,"Trent",Bets!$J$2:$J$506,"Other") | P8: =IF(N8=0,"",O8/N8)
A9: Trent (@BookitWithTrent) | B9: Soccer | C9: =COUNTIFS(Bets!$A$2:$A$506,"<>",Bets!$B$2:$B$506,"Trent",Bets!$J$2:$J$506,"Soccer") | D9: =COUNTIFS(Bets!$A$2:$A$506,"<>",Bets!$B$2:$B$506,"Trent",Bets!$J$2:$J$506,"Soccer",Bets!$U$2:$U$506,"W") | E9: =COUNTIFS(Bets!$A$2:$A$506,"<>",Bets!$B$2:$B$506,"Trent",Bets!$J$2:$J$506,"Soccer",Bets!$U$2:$U$506,"L") | F9: =COUNTIFS(Bets!$A$2:$A$506,"<>",Bets!$B$2:$B$506,"Trent",Bets!$J$2:$J$506,"Soccer",Bets!$U$2:$U$506,"Push") | G9: =COUNTIFS(Bets!$A$2:$A$506,"<>",Bets!$B$2:$B$506,"Trent",Bets!$J$2:$J$506,"Soccer",Bets!$U$2:$U$506,"Pending") | H9: =COUNTIFS(Bets!$A$2:$A$506,"<>",Bets!$B$2:$B$506,"Trent",Bets!$J$2:$J$506,"Soccer",Bets!$U$2:$U$506,"Unknown") | I9: =IF(D9+E9=0,"",D9/(D9+E9)) | J9: =SUMIFS(Bets!$Q$2:$Q$506,Bets!$A$2:$A$506,"<>",Bets!$B$2:$B$506,"Trent",Bets!$J$2:$J$506,"Soccer") | K9: =SUMIFS(Bets!$AC$2:$AC$506,Bets!$A$2:$A$506,"<>",Bets!$B$2:$B$506,"Trent",Bets!$J$2:$J$506,"Soccer") | L9: =SUMIFS(Bets!$V$2:$V$506,Bets!$A$2:$A$506,"<>",Bets!$B$2:$B$506,"Trent",Bets!$J$2:$J$506,"Soccer") | M9: =IF(K9=0,"",L9/K9) | N9: =SUMIFS(Bets!$AD$2:$AD$506,Bets!$A$2:$A$506,"<>",Bets!$B$2:$B$506,"Trent",Bets!$J$2:$J$506,"Soccer") | O9: =SUMIFS(Bets!$W$2:$W$506,Bets!$A$2:$A$506,"<>",Bets!$B$2:$B$506,"Trent",Bets!$J$2:$J$506,"Soccer") | P9: =IF(N9=0,"",O9/N9)
